Workbook
Name RPT_MONTH: Datos!$F$1
Name RPT_SCOPE: _RPT_META!$S$2

Sheet Control
A1: CONTROL DE REPORTE · PLANTA COMPRESORA · SAN MATÍAS PIPELINE
B4: Mes de reporte | C4: =Datos!$F$1 -> 46296 | D4: Espejo de solo lectura de Datos!F1. Para cambiar el mes de reporte usar el selector de la hoja Datos (celda F1).
B5: =IFERROR(HYPERLINK("#'"&_FOTOS_MAP!$K$2&"'!A1","► Ir a las fotos de "&UPPER(CHOOSE(MONTH(RPT_MONTH),"enero","febrero","marzo","abril","mayo","junio","julio","agosto","septiembre","octubre","noviembre","diciembre"))&" "&YEAR(RPT_MONTH)&" ("&_FOTOS_MAP!$K$2&")"),"Seleccione un mes válido para continuar.") -> ► Ir a las fotos de OCTUBRE 2026 (FOTOS_OCT_26)
B6: Estado del control de calidad
B7: Errores | C7: =COUNTIF(_QA!$G$9:$G$81,"ERROR") -> 4
B8: Advertencias | C8: =COUNTIF(_QA!$G$9:$G$81,"ADVERTENCIA") -> 6
B9: Información | C9: =COUNTIF(_QA!$G$9:$G$81,"INFO") -> 4
B10: Semáforo | C10: =IF(C7>0,"ROJO · resolver errores antes de emitir",IF(C8>0,"AMARILLO · revisar advertencias","VERDE")) -> ROJO · resolver errores antes de emitir
B12: Flujo mensual
B13: 1. Cargar el mes en la hoja Datos (columna del mes), las observaciones del seguimiento de SSA en la hoja Observaciones-SMP, las MAPs de OPS en la hoja MAPs y las fotos en la hoja FOTOS_ del mes (acceso directo en B5).
B14: 2. Elegir el mes en C4 y hacer clic en el enlace de B5: abre la hoja FOTOS_ de ese mes. Cargar las fotos solo en esa hoja.
B15: 3. Revisar el semáforo (celda C10) y completar lo que falte en Datos.
B16: 4. Si el semáforo queda en ROJO, informar al responsable del reporte antes de emitir.
B17: 5. Los datasets para gráficos y PowerPoint se actualizan solos (hojas ocultas _HLP_PPT y _FIND_DS).
B18: 6. Cierre: tras un RELEASED, liberar_mes.bat genera cierre_snapshot_*.xlsx (hoja pegar_en__HIST_KPI); pegar sus filas 2 a 36, columnas A:W, como valores en _HIST_KPI, primera fila libre. Los controles H01/H02 vigilan que los meses cerrados no cambien.
B19: 7. Liberación: ejecutar liberar_mes.bat (carpeta Proceso Mensual) sobre este libro calculado y guardado con Excel; genera el PowerPoint, concilia y registra RELEASED o BLOCKED. No se escribe ningún valor a mano.
B20: OPS y Full Control GPS: zonas de pegado _RAW_OPS / _RAW_GPS pendientes de definir con el export real.
B21: Controles de calidad
A22: ID | B22: Control | C22: Observado | D22: Severidad | E22: Estado | F22: Acción sugerida
A23: =_QA!A9 -> P01 | B23: =_QA!C9 -> RPT_MONTH existe en el calendario de Datos (fila 3) | C23: =_QA!E9 -> 0 | D23: =_QA!F9 -> ERROR | E23: =_QA!G9 -> OK | F23: =_QA!H9 -> Elegir un mes válido en Datos!F1
A24: =_QA!A10 -> P02 | B24: =_QA!C10 -> RPT_MONTH es el primer día del mes | C24: =_QA!E10 -> 0 | D24: =_QA!F10 -> ERROR | E24: =_QA!G10 -> OK | F24: =_QA!H10 -> Elegir el mes del desplegable
A25: =_QA!A11 -> P03 | B25: =_QA!C11 -> Fechas de Datos (fila 3) iguales a las de KPIs (fila 3) | C25: =_QA!E11 -> 0 | D25: =_QA!F11 -> ERROR | E25: =_QA!G11 -> OK | F25: =_QA!H11 -> Las columnas de mes deben coincidir
A26: =_QA!A12 -> P04 | B26: =_QA!C12 -> Meses de Datos consecutivos, sin saltos ni repetidos | C26: =_QA!E12 -> 0 | D26: =_QA!F12 -> ERROR | E26: =_QA!G12 -> OK | F26: =_QA!H12 -> Revisar encabezados de mes
A27: =_QA!A13 -> P05 | B27: =_QA!C13 -> Filas de BD_KPIs del mes seleccionado = 37 (21 previstos + 14 YTD + 2 internos IAP/IAE) | C27: =_QA!E13 -> 0 | D27: =_QA!F13 -> ERROR | E27: =_QA!G13 -> OK | F27: =_QA!H13 -> Estructura de BD_KPIs alterada
A28: =_QA!A14 -> P06 | B28: =_QA!C14 -> Jerarquía Cumulative ≥ YTD ≥ Monthly en numeradores (5 KPIs con acumulado) | C28: =_QA!E14 -> 0 | D28: =_QA!F14 -> ERROR | E28: =_QA!G14 -> OK | F28: =_QA!H14 -> Revisar períodos de cálculo
A29: =_QA!A15 -> P07 | B29: =_QA!C15 -> Variables de carga vacías en el mes seleccionado (Datos fila 2) | C29: =_QA!E15 -> 28 | D29: =_QA!F15 -> ADVERTENCIA | E29: =_QA!G15 -> ADVERTENCIA | F29: =_QA!H15 -> Completar Datos del mes o confirmar que no aplica
A30: =_QA!A16 -> P08 | B30: =_QA!C16 -> Hallazgos con fecha de apertura posterior al mes seleccionado | C30: =_QA!E16 -> 0 | D30: =_QA!F16 -> ADVERTENCIA | E30: =_QA!G16 -> OK | F30: =_QA!H16 -> Fecha futura o mes de reporte desactualizado
A31: =_QA!A17 -> P09 | B31: =_QA!C17 -> Hallazgos con fecha de cierre posterior al mes seleccionado | C31: =_QA!E17 -> 0 | D31: =_QA!F17 -> ADVERTENCIA | E31: =_QA!G17 -> OK | F31: =_QA!H17 -> Fecha futura o mes de reporte desactualizado
A32: =_QA!A18 -> P10 | B32: =_QA!C18 -> Base del YTD = año calendario (pendiente de confirmar con el área) | C32: =_QA!E18 -> 1 | D32: =_QA!F18 -> INFO | E32: =_QA!G18 -> INFO | F32: =_QA!H18 -> Confirmar año calendario vs. inicio de proyecto
A33: =_QA!A19 -> D01 | B33: =_QA!C19 -> IDs de hallazgo duplicados | C33: =_QA!E19 -> 0 | D33: =_QA!F19 -> ERROR | E33: =_QA!G19 -> OK | F33: =_QA!H19 -> Corregir ID en Hallazgos col. A
A34: =_QA!A20 -> D02 | B34: =_QA!C20 -> Hallazgos con igual fecha, descripción y área | C34: =_QA!E20 -> 0 | D34: =_QA!F20 -> ADVERTENCIA | E34: =_QA!G20 -> OK | F34: =_QA!H20 -> Posible carga repetida
... A95: =_QA!A81 -> G02 | B95: =_QA!C81 -> Fotos del mes seleccionado sin descripción (pestaña Fotos del mes: 2 por mes) | C95: =_QA!E81 -> 2 | D95: =_QA!F81 -> ADVERTENCIA | E95: =_QA!G81 -> ADVERTENCIA | F95: =_QA!H81 -> Completar la descripción bajo cada foto en la pestaña Fotos del mes seleccionado

Sheet _TARGETS
A1: Code | B1: KPI (ES) | C1: KPI (EN) | D1: Unidad | E1: Sentido | F1: Meta (valor mostrado) | G1: Meta numérica | H1: Estado de la meta | I1: Aplica a | J1: Factor de normalización | K1: Fuente del dato | L1: Fuente de la meta | M1: Vigente desde | N1: Vigente hasta | O1: Confirmación | P1: Tipo de indicador
A2: DAFWCF | B2: =KPIs!$A$6 -> 1 · Frecuencia de casos con días perdidos | C2: Days Away From Work Case Frequency (DAFWCF) | D2: casos / 10^6 HH | E2: ≤ | F2: 0 | G2: 0 | H2: Definida | I2: Monthly / YTD / Cumulative | J2: 1000000 | K2: OPS (carga manual en Datos) | L2: Heredada de plantilla v0 (KPIs!C); documento fuente no identificado | O2: PENDIENTE CONFIRMAR | P2: Tasa
A3: TRICF | B3: =KPIs!$A$7 -> 2 · Frecuencia de casos registrables | C3: Total Recordable Injury Case Frequency (TRICF) | D3: casos / 10^6 HH | E3: ≤ | F3: 2.35 | G3: 2.35 | H3: Definida | I3: Monthly / YTD / Cumulative | J3: 1000000 | K3: OPS (carga manual en Datos) | L3: Heredada de plantilla v0 (KPIs!C); documento fuente no identificado | O3: PENDIENTE CONFIRMAR | P3: Tasa
A4: FAC | B4: =KPIs!$A$8 -> 3 · Casos de primeros auxilios | C4: First Aid Cases (FAC) | D4: casos | F4: Reporte | H4: Solo reporte | I4: Monthly / YTD / Cumulative | J4: 1 | K4: OPS (carga manual en Datos) | L4: Heredada de plantilla v0 (KPIs!C); documento fuente no identificado | O4: PENDIENTE CONFIRMAR | P4: Conteo
A5: SVCR | B5: =KPIs!$A$10 -> 4 · Accidentes vehiculares severos por millón de km | C5: Severe Vehicle Crash Rate (SVCR) | D5: eventos / 10^6 km | F5: Reporte | H5: Solo reporte | I5: Monthly / YTD / Cumulative | J5: 1000000 | K5: OPS (eventos) + Full Control GPS (km) - carga manual en Datos | L5: Heredada de plantilla v0 (KPIs!C); documento fuente no identificado | O5: PENDIENTE CONFIRMAR | P5: Tasa
A6: TVCR | B6: =KPIs!$A$11 -> 5 · Accidentes vehiculares totales por millón de km | C6: Total Vehicle Crash Rate (TVCR) | D6: eventos / 10^6 km | E6: ≤ | F6: 0.79 | G6: 0.79 | H6: Definida | I6: Monthly / YTD / Cumulative | J6: 1000000 | K6: OPS (eventos) + Full Control GPS (km) - carga manual en Datos | L6: Heredada de plantilla v0 (KPIs!C); documento fuente no identificado | O6: PENDIENTE CONFIRMAR | P6: Tasa
A7: OBS | B7: =KPIs!$A$13 -> 6 · Observaciones de seguridad por persona | C7: Safety Observations per Person (OBS) | D7: obs / persona | E7: ≥ | F7: 1 | G7: 1 | H7: PROVISORIA · referencia del subcontratista (OPS: 1 obs/persona); meta y población en definición | I7: Monthly | J7: 1 | K7: OPS (carga manual en Datos) | L7: Referencia OPS para MAPs (sept-26); la meta de 6 obs/persona no definió el personal alcanzado | O7: PENDIENTE CONFIRMAR | P7: Ratio
A8: INV | B8: =KPIs!$A$14 -> 7 · Investigaciones de accidentes: días promedio de cierre | C8: Incident Investigations - Average Closure Days (INV) | D8: días | E8: ≤ | F8: 20 | G8: 20 | H8: Definida | I8: Monthly / YTD | J8: 1 | K8: OPS (carga manual en Datos) | L8: Heredada de plantilla v0 (KPIs!C); documento fuente no identificado | O8: PENDIENTE CONFIRMAR | P8: Promedio
A9: HCS | B9: =KPIs!$A$16 -> 8 · % de capacitación en seguridad | C9: Safety Training Hours as % of Hours Worked (HCS) | D9: % (fracción) | E9: ≥ | F9: 0.01 | G9: 0.01 | H9: Definida | I9: Monthly / YTD | J9: 1 | K9: OPS (carga manual en Datos) | L9: Heredada de plantilla v0 (KPIs!C); documento fuente no identificado | O9: PENDIENTE CONFIRMAR | P9: Proporción
A10: HCSA | B10: =KPIs!$A$17 -> 9 · Horas de capacitación por persona | C10: Safety Training Hours per Person (HCSA) | D10: h / persona | F10: Reporte | H10: Solo reporte | I10: Monthly | J10: 1 | K10: OPS (carga manual en Datos) | L10: Heredada de plantilla v0 (KPIs!C); documento fuente no identificado | O10: PENDIENTE CONFIRMAR | P10: Ratio
A11: CPSE | B11: =KPIs!$A$18 -> 10 · Cumplimiento de simulacros (emergencia y operativos) | C11: Drill Compliance, emergency and operational (CPSE) | D11: % (fracción) | E11: ≥ | F11: 1 | G11: 1 | H11: Definida | I11: Monthly / YTD | J11: 1 | K11: OPS (carga manual en Datos) | L11: Heredada de plantilla v0 (KPIs!C); documento fuente no identificado | O11: PENDIENTE CONFIRMAR | P11: Proporción
A12: CAMS | B12: =KPIs!$A$19 -> 10b · Cumplimiento de acciones de mejora de simulacros | C12: Drill Improvement Actions, implemented vs raised (CAMS) | D12: % (fracción) | F12: Reporte | H12: Solo reporte | I12: Monthly / YTD | J12: 1 | K12: OPS (carga manual en Datos) | L12: Heredada de plantilla v0 (KPIs!C); documento fuente no identificado | O12: PENDIENTE CONFIRMAR | P12: Proporción
A13: ICCS | B13: =KPIs!$A$21 -> 11 · Cumplimiento de caminatas gerenciales | C13: Management Walkthrough Compliance (ICCS) | D13: % (fracción) | E13: ≥ | F13: 1 | G13: 1 | H13: Definida | I13: Monthly / YTD | J13: 1 | K13: OPS (carga manual en Datos) | L13: Heredada de plantilla v0 (KPIs!C); documento fuente no identificado | O13: PENDIENTE CONFIRMAR | P13: Proporción
A14: CCS | B14: =KPIs!$A$22 -> 12 · Cumplimiento de comités y subcomités de seguridad | C14: Safety Committee Compliance (CCS) | D14: % (fracción) | E14: ≥ | F14: 1 | G14: 1 | H14: Definida | I14: Monthly / YTD | J14: 1 | K14: OPS (carga manual en Datos) | L14: Heredada de plantilla v0 (KPIs!C); documento fuente no identificado | O14: PENDIENTE CONFIRMAR | P14: Proporción
A15: DPAS | B15: =KPIs!$A$23 -> 13 · Días promedio para cerrar hallazgos | C15: Average Days to Close Findings (DPAS) | D15: días | E15: ≤ | F15: Medición 2026 (meta en 2027) | H15: Pendiente (meta 2027) | I15: Monthly / YTD | J15: 1 | K15: Plant Findings (hoja Observaciones-SMP) | L15: Heredada de plantilla v0 (KPIs!C); documento fuente no identificado | O15: PENDIENTE CONFIRMAR | P15: Promedio
A16: HAL_ALTA_PCT | B16: =KPIs!$A$33 -> C1 · % de desvíos detectados de gravedad Alta | C16: High-Severity Findings, % of Detected (HAL-A) | D16: % (fracción) | F16: Reporte | H16: Solo reporte | I16: Monthly / YTD | J16: 1 | K16: Plant Findings (hoja Observaciones-SMP) | L16: Heredada de plantilla v0 (KPIs!C); documento fuente no identificado | O16: PENDIENTE CONFIRMAR | P16: Proporción
A17: DET | B17: =KPIs!$A$34 -> C2 · Detenciones de tareas aplicadas | C17: Stop-Work Actions Applied (DET) | D17: u | F17: Reporte | H17: Solo reporte | I17: Monthly / YTD | J17: 1 | K17: Plant Findings (hoja Observaciones-SMP) | L17: Heredada de plantilla v0 (KPIs!C); documento fuente no identificado | O17: PENDIENTE CONFIRMAR | P17: Conteo
A18: COB | B18: =KPIs!$A$53 -> 14 · COB – Cobertura de capacitación en seguridad | C18: Safety Training Coverage (COB) | D18: % (fracción) | F18: Reporte | H18: Solo reporte | I18: Monthly | J18: 1 | K18: Carga manual en Datos (planillas de asistencia) | L18: Definición de la Gerencia (V2); sin meta | O18: PENDIENTE CONFIRMAR | P18: Proporción
A19: CAMPC | B19: =KPIs!$A$54 -> 15 · CAMPC – Cumplimiento de campañas de seguridad | C19: Safety Campaign Compliance (CAMPC) | D19: % (fracción) | F19: Reporte | H19: Solo reporte | I19: Monthly | J19: 1 | K19: Carga manual en Datos (evidencia de campañas) | L19: Definición de la Gerencia (V2); sin meta | O19: PENDIENTE CONFIRMAR | P19: Proporción

Sheet Datos
B1: DATOS MENSUALES HSE · PLANTA COMPRESORA · OPS + SMP(IEBC, PAE e YPF) EN CAMPO | D1: MES DE REPORTE ▶ | F1: 46296 | W1: =IFERROR(HYPERLINK("#'"&_FOTOS_MAP!$K$2&"'!A1","► Ir a las fotos de "&UPPER(CHOOSE(MONTH(RPT_MONTH),"enero","febrero","marzo","abril","mayo","junio","julio","agosto","septiembre","octubre","noviembre","diciembre"))&" "&YEAR(RPT_MONTH)&" ("&_FOTOS_MAP!$K$2&")"),"Seleccione un mes válido para continuar.") -> ► Ir a las fotos de OCTUBRE 2026 (FOTOS_OCT_26)
B2: Amarillo: por cargar · Naranja: falta cargar (mes en curso o pasado) · Verde: cargado · Celeste: mes a cargar · Rojo fuerte: revisar (dato incoherente) | C2: Estado | D2: =IF($D$3>RPT_MONTH,"",COUNTBLANK(D9:D10)+COUNTBLANK(D12:D13)+COUNTBLANK(D16:D17)+COUNTBLANK(D20:D31)+COUNTBLANK(D33:D37)+COUNTBLANK(D39:D42)+COUNTBLANK(D44:D46)) -> 0 | E2: =IF($E$3>RPT_MONTH,"",COUNTBLANK(E9:E10)+COUNTBLANK(E12:E13)+COUNTBLANK(E16:E17)+COUNTBLANK(E20:E31)+COUNTBLANK(E33:E37)+COUNTBLANK(E39:E42)+COUNTBLANK(E44:E46)) -> 0 | F2: =IF($F$3>RPT_MONTH,"",COUNTBLANK(F9:F10)+COUNTBLANK(F12:F13)+COUNTBLANK(F16:F17)+COUNTBLANK(F20:F31)+COUNTBLANK(F33:F37)+COUNTBLANK(F39:F42)+COUNTBLANK(F44:F46)) -> 28 | G2: =IF($G$3>RPT_MONTH,"",COUNTBLANK(G9:G10)+COUNTBLANK(G12:G13)+COUNTBLANK(G16:G17)+COUNTBLANK(G20:G31)+COUNTBLANK(G33:G37)+COUNTBLANK(G39:G42)+COUNTBLANK(G44:G46)) | H2: =IF($H$3>RPT_MONTH,"",COUNTBLANK(H9:H10)+COUNTBLANK(H12:H13)+COUNTBLANK(H16:H17)+COUNTBLANK(H20:H31)+COUNTBLANK(H33:H37)+COUNTBLANK(H39:H42)+COUNTBLANK(H44:H46)) | I2: =IF($I$3>RPT_MONTH,"",COUNTBLANK(I9:I10)+COUNTBLANK(I12:I13)+COUNTBLANK(I16:I17)+COUNTBLANK(I20:I31)+COUNTBLANK(I33:I37)+COUNTBLANK(I39:I42)+COUNTBLANK(I44:I46)) | J2: =IF($J$3>RPT_MONTH,"",COUNTBLANK(J9:J10)+COUNTBLANK(J12:J13)+COUNTBLANK(J16:J17)+COUNTBLANK(J20:J31)+COUNTBLANK(J33:J37)+COUNTBLANK(J39:J42)+COUNTBLANK(J44:J46)) | K2: =IF($K$3>RPT_MONTH,"",COUNTBLANK(K9:K10)+COUNTBLANK(K12:K13)+COUNTBLANK(K16:K17)+COUNTBLANK(K20:K31)+COUNTBLANK(K33:K37)+COUNTBLANK(K39:K42)+COUNTBLANK(K44:K46)) | L2: =IF($L$3>RPT_MONTH,"",COUNTBLANK(L9:L10)+COUNTBLANK(L12:L13)+COUNTBLANK(L16:L17)+COUNTBLANK(L20:L31)+COUNTBLANK(L33:L37)+COUNTBLANK(L39:L42)+COUNTBLANK(L44:L46)) | M2: =IF($M$3>RPT_MONTH,"",COUNTBLANK(M9:M10)+COUNTBLANK(M12:M13)+COUNTBLANK(M16:M17)+COUNTBLANK(M20:M31)+COUNTBLANK(M33:M37)+COUNTBLANK(M39:M42)+COUNTBLANK(M44:M46)) | N2: =IF($N$3>RPT_MONTH,"",COUNTBLANK(N9:N10)+COUNTBLANK(N12:N13)+COUNTBLANK(N16:N17)+COUNTBLANK(N20:N31)+COUNTBLANK(N33:N37)+COUNTBLANK(N39:N42)+COUNTBLANK(N44:N46)) | O2: =IF($O$3>RPT_MONTH,"",COUNTBLANK(O9:O10)+COUNTBLANK(O12:O13)+COUNTBLANK(O16:O17)+COUNTBLANK(O20:O31)+COUNTBLANK(O33:O37)+COUNTBLANK(O39:O42)+COUNTBLANK(O44:O46)) | P2: =IF($P$3>RPT_MONTH,"",COUNTBLANK(P9:P10)+COUNTBLANK(P12:P13)+COUNTBLANK(P16:P17)+COUNTBLANK(P20:P31)+COUNTBLANK(P33:P37)+COUNTBLANK(P39:P42)+COUNTBLANK(P44:P46)) | Q2: =IF($Q$3>RPT_MONTH,"",COUNTBLANK(Q9:Q10)+COUNTBLANK(Q12:Q13)+COUNTBLANK(Q16:Q17)+COUNTBLANK(Q20:Q31)+COUNTBLANK(Q33:Q37)+COUNTBLANK(Q39:Q42)+COUNTBLANK(Q44:Q46)) | R2: =IF($R$3>RPT_MONTH,"",COUNTBLANK(R9:R10)+COUNTBLANK(R12:R13)+COUNTBLANK(R16:R17)+COUNTBLANK(R20:R31)+COUNTBLANK(R33:R37)+COUNTBLANK(R39:R42)+COUNTBLANK(R44:R46)) | S2: =IF($S$3>RPT_MONTH,"",COUNTBLANK(S9:S10)+COUNTBLANK(S12:S13)+COUNTBLANK(S16:S17)+COUNTBLANK(S20:S31)+COUNTBLANK(S33:S37)+COUNTBLANK(S39:S42)+COUNTBLANK(S44:S46)) | T2: =IF($T$3>RPT_MONTH,"",COUNTBLANK(T9:T10)+COUNTBLANK(T12:T13)+COUNTBLANK(T16:T17)+COUNTBLANK(T20:T31)+COUNTBLANK(T33:T37)+COUNTBLANK(T39:T42)+COUNTBLANK(T44:T46)) | U2: =IF($U$3>RPT_MONTH,"",COUNTBLANK(U9:U10)+COUNTBLANK(U12:U13)+COUNTBLANK(U16:U17)+COUNTBLANK(U20:U31)+COUNTBLANK(U33:U37)+COUNTBLANK(U39:U42)+COUNTBLANK(U44:U46)) | V2: =IF($V$3>RPT_MONTH,"",COUNTBLANK(V9:V10)+COUNTBLANK(V12:V13)+COUNTBLANK(V16:V17)+COUNTBLANK(V20:V31)+COUNTBLANK(V33:V37)+COUNTBLANK(V39:V42)+COUNTBLANK(V44:V46)) | W2: =IF($W$3>RPT_MONTH,"",COUNTBLANK(W9:W10)+COUNTBLANK(W12:W13)+COUNTBLANK(W16:W17)+COUNTBLANK(W20:W31)+COUNTBLANK(W33:W37)+COUNTBLANK(W39:W42)+COUNTBLANK(W44:W46)) | X2: =IF($X$3>RPT_MONTH,"",COUNTBLANK(X9:X10)+COUNTBLANK(X12:X13)+COUNTBLANK(X16:X17)+COUNTBLANK(X20:X31)+COUNTBLANK(X33:X37)+COUNTBLANK(X39:X42)+COUNTBLANK(X44:X46)) | Y2: =IF($Y$3>RPT_MONTH,"",COUNTBLANK(Y9:Y10)+COUNTBLANK(Y12:Y13)+COUNTBLANK(Y16:Y17)+COUNTBLANK(Y20:Y31)+COUNTBLANK(Y33:Y37)+COUNTBLANK(Y39:Y42)+COUNTBLANK(Y44:Y46)) | Z2: =IF($Z$3>RPT_MONTH,"",COUNTBLANK(Z9:Z10)+COUNTBLANK(Z12:Z13)+COUNTBLANK(Z16:Z17)+COUNTBLANK(Z20:Z31)+COUNTBLANK(Z33:Z37)+COUNTBLANK(Z39:Z42)+COUNTBLANK(Z44:Z46)) | AA2: =IF($AA$3>RPT_MONTH,"",COUNTBLANK(AA9:AA10)+COUNTBLANK(AA12:AA13)+COUNTBLANK(AA16:AA17)+COUNTBLANK(AA20:AA31)+COUNTBLANK(AA33:AA37)+COUNTBLANK(AA39:AA42)+COUNTBLANK(AA44:AA46)) | AB2: =IF($AB$3>RPT_MONTH,"",COUNTBLANK(AB9:AB10)+COUNTBLANK(AB12:AB13)+COUNTBLANK(AB16:AB17)+COUNTBLANK(AB20:AB31)+COUNTBLANK(AB33:AB37)+COUNTBLANK(AB39:AB42)+COUNTBLANK(AB44:AB46)) | AC2: =IF($AC$3>RPT_MONTH,"",COUNTBLANK(AC9:AC10)+COUNTBLANK(AC12:AC13)+COUNTBLANK(AC16:AC17)+COUNTBLANK(AC20:AC31)+COUNTBLANK(AC33:AC37)+COUNTBLANK(AC39:AC42)+COUNTBLANK(AC44:AC46)) | AD2: =IF($AD$3>RPT_MONTH,"",COUNTBLANK(AD9:AD10)+COUNTBLANK(AD12:AD13)+COUNTBLANK(AD16:AD17)+COUNTBLANK(AD20:AD31)+COUNTBLANK(AD33:AD37)+COUNTBLANK(AD39:AD42)+COUNTBLANK(AD44:AD46)) | AE2: =IF($AE$3>RPT_MONTH,"",COUNTBLANK(AE9:AE10)+COUNTBLANK(AE12:AE13)+COUNTBLANK(AE16:AE17)+COUNTBLANK(AE20:AE31)+COUNTBLANK(AE33:AE37)+COUNTBLANK(AE39:AE42)+COUNTBLANK(AE44:AE46)) | AF2: =IF($AF$3>RPT_MONTH,"",COUNTBLANK(AF9:AF10)+COUNTBLANK(AF12:AF13)+COUNTBLANK(AF16:AF17)+COUNTBLANK(AF20:AF31)+COUNTBLANK(AF33:AF37)+COUNTBLANK(AF39:AF42)+COUNTBLANK(AF44:AF46)) | AG2: =IF($AG$3>RPT_MONTH,"",COUNTBLANK(AG9:AG10)+COUNTBLANK(AG12:AG13)+COUNTBLANK(AG16:AG17)+COUNTBLANK(AG20:AG31)+COUNTBLANK(AG33:AG37)+COUNTBLANK(AG39:AG42)+COUNTBLANK(AG44:AG46)) | AH2: =IF($AH$3>RPT_MONTH,"",COUNTBLANK(AH9:AH10)+COUNTBLANK(AH12:AH13)+COUNTBLANK(AH16:AH17)+COUNTBLANK(AH20:AH31)+COUNTBLANK(AH33:AH37)+COUNTBLANK(AH39:AH42)+COUNTBLANK(AH44:AH46)) | AI2: =IF($AI$3>RPT_MONTH,"",COUNTBLANK(AI9:AI10)+COUNTBLANK(AI12:AI13)+COUNTBLANK(AI16:AI17)+COUNTBLANK(AI20:AI31)+COUNTBLANK(AI33:AI37)+COUNTBLANK(AI39:AI42)+COUNTBLANK(AI44:AI46)) | AJ2: =IF($AJ$3>RPT_MONTH,"",COUNTBLANK(AJ9:AJ10)+COUNTBLANK(AJ12:AJ13)+COUNTBLANK(AJ16:AJ17)+COUNTBLANK(AJ20:AJ31)+COUNTBLANK(AJ33:AJ37)+COUNTBLANK(AJ39:AJ42)+COUNTBLANK(AJ44:AJ46)) | AK2: =IF($AK$3>RPT_MONTH,"",COUNTBLANK(AK9:AK10)+COUNTBLANK(AK12:AK13)+COUNTBLANK(AK16:AK17)+COUNTBLANK(AK20:AK31)+COUNTBLANK(AK33:AK37)+COUNTBLANK(AK39:AK42)+COUNTBLANK(AK44:AK46)) | AL2: =IF($AL$3>RPT_MONTH,"",COUNTBLANK(AL9:AL10)+COUNTBLANK(AL12:AL13)+COUNTBLANK(AL16:AL17)+COUNTBLANK(AL20:AL31)+COUNTBLANK(AL33:AL37)+COUNTBLANK(AL39:AL42)+COUNTBLANK(AL44:AL46))
A3: SIGLA (YPF) | B3: VARIABLE | C3: Unidad | D3: 46235 | E3: 46266 | F3: 46296 | G3: 46327 | H3: 46357 | I3: 46388 | J3: 46419 | K3: 46447 | L3: 46478 | M3: 46508 | N3: 46539 | O3: 46569 | P3: 46600 | Q3: 46631 | R3: 46661 | S3: 46692 | T3: 46722 | U3: 46753 | V3: 46784 | W3: 46813 | X3: 46844 | Y3: 46874 | Z3: 46905 | AA3: 46935 | AB3: 46966 | AC3: 46997 | AD3: 47027 | AE3: 47058 | AF3: 47088 | AG3: 47119 | AH3: 47150 | AI3: 47178 | AJ3: 47209 | AK3: 47239 | AL3: 47270
D4: Compresora | E4: Compresora | F4: Compresora | G4: Compresora | H4: Compresora | I4: Compresora | J4: Compresora | K4: Compresora | L4: Compresora | M4: Compresora | N4: Compresora | O4: Compresora | P4: Compresora | Q4: Compresora | R4: Compresora | S4: Compresora | T4: Compresora | U4: Compresora | V4: Compresora | W4: Compresora | X4: Compresora | Y4: Compresora | Z4: Compresora | AA4: Compresora | AB4: Compresora | AC4: Compresora | AD4: Compresora | AE4: Compresora | AF4: Compresora | AG4: Compresora | AH4: Compresora | AI4: Compresora | AJ4: Compresora | AK4: Compresora | AL4: Compresora
B5: PERSONAL EN CAMPO · OPS + SMP(IEBC, PAE e YPF)
A6: PTOT(?) | B6: Personal total del mes: Personal OPS | C6: pers | D6: 83 | E6: 112
A7: PTOT(?) | B7: Personal total del mes: Personal SMP(IEBC, PAE e YPF) en campo | C7: pers | D7: 9 | E7: 11
A8: PTOT(?) | B8: Personal total del mes: TOTAL | C8: pers | D8: =D6+D7 -> 92 | E8: =E6+E7 -> 123 | F8: =F6+F7 -> 0 | G8: =G6+G7 -> 0 | H8: =H6+H7 -> 0 | I8: =I6+I7 -> 0 | J8: =J6+J7 -> 0 | K8: =K6+K7 -> 0 | ... AL8: =AL6+AL7 -> 0
A9: NTTP(?) | B9: Dotación promedio: Personal OPS | C9: pers | D9: 83 | E9: 112
A10: NTTP(?) | B10: Dotación promedio: Personal SMP(IEBC, PAE e YPF) | C10: pers | D10: 9 | E10: 11
A11: NTTP(?) | B11: Dotación promedio: TOTAL | C11: pers | D11: =D9+D10 -> 92 | E11: =E9+E10 -> 123 | F11: =F9+F10 -> 0 | G11: =G9+G10 -> 0 | H11: =H9+H10 -> 0 | I11: =I9+I10 -> 0 | J11: =J9+J10 -> 0 | K11: =K9+K10 -> 0 | ... AL11: =AL9+AL10 -> 0
A12: HHT(?) | B12: Horas hombre trabajadas: Personal OPS | C12: h | D12: 21008 | E12: 23166
A13: HHT(?) | B13: Horas hombre trabajadas: Personal SMP(IEBC, PAE e YPF) en campo | C13: h | D13: 1980 | E13: 2178
A14: HHT(?) | B14: Horas hombre trabajadas: TOTAL | C14: h | D14: =D12+D13 -> 22988 | E14: =E12+E13 -> 25344 | F14: =F12+F13 -> 0 | G14: =G12+G13 -> 0 | H14: =H12+H13 -> 0 | I14: =I12+I13 -> 0 | J14: =J12+J13 -> 0 | K14: =K12+K13 -> 0 | ... AL14: =AL12+AL13 -> 0
B15: CAPACITACIÓN EN SEGURIDAD
A16: HHS(?) | B16: Horas hombre de formación en seguridad: Personal OPS | C16: h | D16: 1143 | E16: 781
A17: HHS(?) | B17: Horas hombre de formación en seguridad: Personal SMP(IEBC, PAE e YPF) | C17: h | D17: 117 | E17: 110
A18: HHS(?) | B18: Horas hombre de formación en seguridad: TOTAL | C18: h | D18: =D16+D17 -> 1260 | E18: =E16+E17 -> 891 | F18: =F16+F17 -> 0 | G18: =G16+G17 -> 0 | H18: =H16+H17 -> 0 | I18: =I16+I17 -> 0 | J18: =J16+J17 -> 0 | K18: =K16+K17 -> 0 | ... AL18: =AL16+AL17 -> 0
B19: GESTIÓN
A20: SIMR(?) | B20: SIMULACROS · Realizados (emergencia y operativos) | C20: u | D20: 1 | E20: 2
A21: SIMP(?) | B21: SIMULACROS · Programados (emergencia y operativos) | C21: u | D21: 1 | E21: 2
A22: AMS(?) | B22: SIMULACROS · Acciones de mejora surgidas de los simulacros (en el mes informado) | C22: u | D22: 0 | E22: 1
A23: AMI(ICME) | B23: SIMULACROS · Acciones de mejora implementadas surgidas de los simulacros (ICME) (en el mes informado) | C23: u | D23: 0 | E23: 1
A24: ICCS(?) | B24: Caminatas gerenciales realizadas | C24: u | D24: 0 | E24: 3
A25: ICCS(?) | B25: Caminatas gerenciales planificadas | C25: u | D25: 0 | E25: 3
A26: CCS(?) | B26: Comités y subcomités de seguridad realizados | C26: u | D26: 0 | E26: 1
A27: CCS(?) | B27: Comités y subcomités de seguridad planificados | C27: u | D27: 0 | E27: 1
A28: OCS(?) | B28: Observaciones de comportamiento: abiertas (Total: OPS+SMP) | C28: u | D28: =IF(OR(D$3>RPT_MONTH,AND(COUNT(D64:D65)=0,D78=0)),"",SUM(D65,D78)-SUMPRODUCT(('Observaciones-SMP'!$B$2:$B$1001>=D$3)*('Observaciones-SMP'!$B$2:$B$1001<(EOMONTH(D$3,0)+1))*--((('Observaciones-SMP'!$O$2:$O$1001="Cerrado")+('Observaciones-SMP'!$O$2:$O$1001="Cerrada")+(((ISNUMBER(SEARCH("estándar",'Observaciones-SMP'!$I$2:$I$1001))*ISERROR(SEARCH("sub",'Observaciones-SMP'!$I$2:$I$1001)))+ISNUMBER(SEARCH("positiv",'Observaciones-SMP'!$I$2:$I$1001))+ISNUMBER(SEARCH("buena pr",'Observaciones-SMP'!$I$2:$I$1001)))>0))>0))) -> 6 | E28: =IF(OR(E$3>RPT_MONTH,AND(COUNT(E64:E65)=0,E78=0)),"",SUM(E65,E78)-SUMPRODUCT(('Observaciones-SMP'!$B$2:$B$1001>=E$3)*('Observaciones-SMP'!$B$2:$B$1001<(EOMONTH(E$3,0)+1))*--((('Observaciones-SMP'!$O$2:$O$1001="Cerrado")+('Observaciones-SMP'!$O$2:$O$1001="Cerrada")+(((ISNUMBER(SEARCH("estándar",'Observaciones-SMP'!$I$2:$I$1001))*ISERROR(SEARCH("sub",'Observaciones-SMP'!$I$2:$I$1001)))+ISNUMBER(SEARCH("positiv",'Observaciones-SMP'!$I$2:$I$1001))+ISNUMBER(SEARCH("buena pr",'Observaciones-SMP'!$I$2:$I$1001)))>0))>0))) -> 86 | F28: =IF(OR(F$3>RPT_MONTH,AND(COUNT(F64:F65)=0,F78=0)),"",SUM(F65,F78)-SUMPRODUCT(('Observaciones-SMP'!$B$2:$B$1001>=F$3)*('Observaciones-SMP'!$B$2:$B$1001<(EOMONTH(F$3,0)+1))*--((('Observaciones-SMP'!$O$2:$O$1001="Cerrado")+('Observaciones-SMP'!$O$2:$O$1001="Cerrada")+(((ISNUMBER(SEARCH("estándar",'Observaciones-SMP'!$I$2:$I$1001))*ISERROR(SEARCH("sub",'Observaciones-SMP'!$I$2:$I$1001)))+ISNUMBER(SEARCH("positiv",'Observaciones-SMP'!$I$2:$I$1001))+ISNUMBER(SEARCH("buena pr",'Observaciones-SMP'!$I$2:$I$1001)))>0))>0))) -> 0 | G28: =IF(OR(G$3>RPT_MONTH,AND(COUNT(G64:G65)=0,G78=0)),"",SUM(G65,G78)-SUMPRODUCT(('Observaciones-SMP'!$B$2:$B$1001>=G$3)*('Observaciones-SMP'!$B$2:$B$1001<(EOMONTH(G$3,0)+1))*--((('Observaciones-SMP'!$O$2:$O$1001="Cerrado")+('Observaciones-SMP'!$O$2:$O$1001="Cerrada")+(((ISNUMBER(SEARCH("estándar",'Observaciones-SMP'!$I$2:$I$1001))*ISERROR(SEARCH("sub",'Observaciones-SMP'!$I$2:$I$1001)))+ISNUMBER(SEARCH("positiv",'Observaciones-SMP'!$I$2:$I$1001))+ISNUMBER(SEARCH("buena pr",'Observaciones-SMP'!$I$2:$I$1001)))>0))>0))) | H28: =IF(OR(H$3>RPT_MONTH,AND(COUNT(H64:H65)=0,H78=0)),"",SUM(H65,H78)-SUMPRODUCT(('Observaciones-SMP'!$B$2:$B$1001>=H$3)*('Observaciones-SMP'!$B$2:$B$1001<(EOMONTH(H$3,0)+1))*--((('Observaciones-SMP'!$O$2:$O$1001="Cerrado")+('Observaciones-SMP'!$O$2:$O$1001="Cerrada")+(((ISNUMBER(SEARCH("estándar",'Observaciones-SMP'!$I$2:$I$1001))*ISERROR(SEARCH("sub",'Observaciones-SMP'!$I$2:$I$1001)))+ISNUMBER(SEARCH("positiv",'Observaciones-SMP'!$I$2:$I$1001))+ISNUMBER(SEARCH("buena pr",'Observaciones-SMP'!$I$2:$I$1001)))>0))>0))) | I28: =IF(OR(I$3>RPT_MONTH,AND(COUNT(I64:I65)=0,I78=0)),"",SUM(I65,I78)-SUMPRODUCT(('Observaciones-SMP'!$B$2:$B$1001>=I$3)*('Observaciones-SMP'!$B$2:$B$1001<(EOMONTH(I$3,0)+1))*--((('Observaciones-SMP'!$O$2:$O$1001="Cerrado")+('Observaciones-SMP'!$O$2:$O$1001="Cerrada")+(((ISNUMBER(SEARCH("estándar",'Observaciones-SMP'!$I$2:$I$1001))*ISERROR(SEARCH("sub",'Observaciones-SMP'!$I$2:$I$1001)))+ISNUMBER(SEARCH("positiv",'Observaciones-SMP'!$I$2:$I$1001))+ISNUMBER(SEARCH("buena pr",'Observaciones-SMP'!$I$2:$I$1001)))>0))>0))) | J28: =IF(OR(J$3>RPT_MONTH,AND(COUNT(J64:J65)=0,J78=0)),"",SUM(J65,J78)-SUMPRODUCT(('Observaciones-SMP'!$B$2:$B$1001>=J$3)*('Observaciones-SMP'!$B$2:$B$1001<(EOMONTH(J$3,0)+1))*--((('Observaciones-SMP'!$O$2:$O$1001="Cerrado")+('Observaciones-SMP'!$O$2:$O$1001="Cerrada")+(((ISNUMBER(SEARCH("estándar",'Observaciones-SMP'!$I$2:$I$1001))*ISERROR(SEARCH("sub",'Observaciones-SMP'!$I$2:$I$1001)))+ISNUMBER(SEARCH("positiv",'Observaciones-SMP'!$I$2:$I$1001))+ISNUMBER(SEARCH("buena pr",'Observaciones-SMP'!$I$2:$I$1001)))>0))>0))) | K28: =IF(OR(K$3>RPT_MONTH,AND(COUNT(K64:K65)=0,K78=0)),"",SUM(K65,K78)-SUMPRODUCT(('Observaciones-SMP'!$B$2:$B$1001>=K$3)*('Observaciones-SMP'!$B$2:$B$1001<(EOMONTH(K$3,0)+1))*--((('Observaciones-SMP'!$O$2:$O$1001="Cerrado")+('Observaciones-SMP'!$O$2:$O$1001="Cerrada")+(((ISNUMBER(SEARCH("estándar",'Observaciones-SMP'!$I$2:$I$1001))*ISERROR(SEARCH("sub",'Observaciones-SMP'!$I$2:$I$1001)))+ISNUMBER(SEARCH("positiv",'Observaciones-SMP'!$I$2:$I$1001))+ISNUMBER(SEARCH("buena pr",'Observaciones-SMP'!$I$2:$I$1001)))>0))>0))) | ... AL28: =IF(OR(AL$3>RPT_MONTH,AND(COUNT(AL64:AL65)=0,AL78=0)),"",SUM(AL65,AL78)-SUMPRODUCT(('Observaciones-SMP'!$B$2:$B$1001>=AL$3)*('Observaciones-SMP'!$B$2:$B$1001<(EOMONTH(AL$3,0)+1))*--((('Observaciones-SMP'!$O$2:$O$1001="Cerrado")+('Observaciones-SMP'!$O$2:$O$1001="Cerrada")+(((ISNUMBER(SEARCH("estándar",'Observaciones-SMP'!$I$2:$I$1001))*ISERROR(SEARCH("sub",'Observaciones-SMP'!$I$2:$I$1001)))+ISNUMBER(SEARCH("positiv",'Observaciones-SMP'!$I$2:$I$1001))+ISNUMBER(SEARCH("buena pr",'Observaciones-SMP'!$I$2:$I$1001)))>0))>0)))
B29: Observaciones de comportamiento seguro: cerradas y positivas (Total: OPS+SMP) | C29: u | D29: =IF(OR(D$3>RPT_MONTH,AND(COUNT(D64:D65)=0,D78=0)),"",SUM(D64,SUMPRODUCT(('Observaciones-SMP'!$B$2:$B$1001>=D$3)*('Observaciones-SMP'!$B$2:$B$1001<(EOMONTH(D$3,0)+1))*--((('Observaciones-SMP'!$O$2:$O$1001="Cerrado")+('Observaciones-SMP'!$O$2:$O$1001="Cerrada")+(((ISNUMBER(SEARCH("estándar",'Observaciones-SMP'!$I$2:$I$1001))*ISERROR(SEARCH("sub",'Observaciones-SMP'!$I$2:$I$1001)))+ISNUMBER(SEARCH("positiv",'Observaciones-SMP'!$I$2:$I$1001))+ISNUMBER(SEARCH("buena pr",'Observaciones-SMP'!$I$2:$I$1001)))>0))>0)))) -> 29 | E29: =IF(OR(E$3>RPT_MONTH,AND(COUNT(E64:E65)=0,E78=0)),"",SUM(E64,SUMPRODUCT(('Observaciones-SMP'!$B$2:$B$1001>=E$3)*('Observaciones-SMP'!$B$2:$B$1001<(EOMONTH(E$3,0)+1))*--((('Observaciones-SMP'!$O$2:$O$1001="Cerrado")+('Observaciones-SMP'!$O$2:$O$1001="Cerrada")+(((ISNUMBER(SEARCH("estándar",'Observaciones-SMP'!$I$2:$I$1001))*ISERROR(SEARCH("sub",'Observaciones-SMP'!$I$2:$I$1001)))+ISNUMBER(SEARCH("positiv",'Observaciones-SMP'!$I$2:$I$1001))+ISNUMBER(SEARCH("buena pr",'Observaciones-SMP'!$I$2:$I$1001)))>0))>0)))) -> 91 | F29: =IF(OR(F$3>RPT_MONTH,AND(COUNT(F64:F65)=0,F78=0)),"",SUM(F64,SUMPRODUCT(('Observaciones-SMP'!$B$2:$B$1001>=F$3)*('Observaciones-SMP'!$B$2:$B$1001<(EOMONTH(F$3,0)+1))*--((('Observaciones-SMP'!$O$2:$O$1001="Cerrado")+('Observaciones-SMP'!$O$2:$O$1001="Cerrada")+(((ISNUMBER(SEARCH("estándar",'Observaciones-SMP'!$I$2:$I$1001))*ISERROR(SEARCH("sub",'Observaciones-SMP'!$I$2:$I$1001)))+ISNUMBER(SEARCH("positiv",'Observaciones-SMP'!$I$2:$I$1001))+ISNUMBER(SEARCH("buena pr",'Observaciones-SMP'!$I$2:$I$1001)))>0))>0)))) -> 3 | G29: =IF(OR(G$3>RPT_MONTH,AND(COUNT(G64:G65)=0,G78=0)),"",SUM(G64,SUMPRODUCT(('Observaciones-SMP'!$B$2:$B$1001>=G$3)*('Observaciones-SMP'!$B$2:$B$1001<(EOMONTH(G$3,0)+1))*--((('Observaciones-SMP'!$O$2:$O$1001="Cerrado")+('Observaciones-SMP'!$O$2:$O$1001="Cerrada")+(((ISNUMBER(SEARCH("estándar",'Observaciones-SMP'!$I$2:$I$1001))*ISERROR(SEARCH("sub",'Observaciones-SMP'!$I$2:$I$1001)))+ISNUMBER(SEARCH("positiv",'Observaciones-SMP'!$I$2:$I$1001))+ISNUMBER(SEARCH("buena pr",'Observaciones-SMP'!$I$2:$I$1001)))>0))>0)))) | H29: =IF(OR(H$3>RPT_MONTH,AND(COUNT(H64:H65)=0,H78=0)),"",SUM(H64,SUMPRODUCT(('Observaciones-SMP'!$B$2:$B$1001>=H$3)*('Observaciones-SMP'!$B$2:$B$1001<(EOMONTH(H$3,0)+1))*--((('Observaciones-SMP'!$O$2:$O$1001="Cerrado")+('Observaciones-SMP'!$O$2:$O$1001="Cerrada")+(((ISNUMBER(SEARCH("estándar",'Observaciones-SMP'!$I$2:$I$1001))*ISERROR(SEARCH("sub",'Observaciones-SMP'!$I$2:$I$1001)))+ISNUMBER(SEARCH("positiv",'Observaciones-SMP'!$I$2:$I$1001))+ISNUMBER(SEARCH("buena pr",'Observaciones-SMP'!$I$2:$I$1001)))>0))>0)))) | I29: =IF(OR(I$3>RPT_MONTH,AND(COUNT(I64:I65)=0,I78=0)),"",SUM(I64,SUMPRODUCT(('Observaciones-SMP'!$B$2:$B$1001>=I$3)*('Observaciones-SMP'!$B$2:$B$1001<(EOMONTH(I$3,0)+1))*--((('Observaciones-SMP'!$O$2:$O$1001="Cerrado")+('Observaciones-SMP'!$O$2:$O$1001="Cerrada")+(((ISNUMBER(SEARCH("estándar",'Observaciones-SMP'!$I$2:$I$1001))*ISERROR(SEARCH("sub",'Observaciones-SMP'!$I$2:$I$1001)))+ISNUMBER(SEARCH("positiv",'Observaciones-SMP'!$I$2:$I$1001))+ISNUMBER(SEARCH("buena pr",'Observaciones-SMP'!$I$2:$I$1001)))>0))>0)))) | J29: =IF(OR(J$3>RPT_MONTH,AND(COUNT(J64:J65)=0,J78=0)),"",SUM(J64,SUMPRODUCT(('Observaciones-SMP'!$B$2:$B$1001>=J$3)*('Observaciones-SMP'!$B$2:$B$1001<(EOMONTH(J$3,0)+1))*--((('Observaciones-SMP'!$O$2:$O$1001="Cerrado")+('Observaciones-SMP'!$O$2:$O$1001="Cerrada")+(((ISNUMBER(SEARCH("estándar",'Observaciones-SMP'!$I$2:$I$1001))*ISERROR(SEARCH("sub",'Observaciones-SMP'!$I$2:$I$1001)))+ISNUMBER(SEARCH("positiv",'Observaciones-SMP'!$I$2:$I$1001))+ISNUMBER(SEARCH("buena pr",'Observaciones-SMP'!$I$2:$I$1001)))>0))>0)))) | K29: =IF(OR(K$3>RPT_MONTH,AND(COUNT(K64:K65)=0,K78=0)),"",SUM(K64,SUMPRODUCT(('Observaciones-SMP'!$B$2:$B$1001>=K$3)*('Observaciones-SMP'!$B$2:$B$1001<(EOMONTH(K$3,0)+1))*--((('Observaciones-SMP'!$O$2:$O$1001="Cerrado")+('Observaciones-SMP'!$O$2:$O$1001="Cerrada")+(((ISNUMBER(SEARCH("estándar",'Observaciones-SMP'!$I$2:$I$1001))*ISERROR(SEARCH("sub",'Observaciones-SMP'!$I$2:$I$1001)))+ISNUMBER(SEARCH("positiv",'Observaciones-SMP'!$I$2:$I$1001))+ISNUMBER(SEARCH("buena pr",'Observaciones-SMP'!$I$2:$I$1001)))>0))>0)))) | ... AL29: =IF(OR(AL$3>RPT_MONTH,AND(COUNT(AL64:AL65)=0,AL78=0)),"",SUM(AL64,SUMPRODUCT(('Observaciones-SMP'!$B$2:$B$1001>=AL$3)*('Observaciones-SMP'!$B$2:$B$1001<(EOMONTH(AL$3,0)+1))*--((('Observaciones-SMP'!$O$2:$O$1001="Cerrado")+('Observaciones-SMP'!$O$2:$O$1001="Cerrada")+(((ISNUMBER(SEARCH("estándar",'Observaciones-SMP'!$I$2:$I$1001))*ISERROR(SEARCH("sub",'Observaciones-SMP'!$I$2:$I$1001)))+ISNUMBER(SEARCH("positiv",'Observaciones-SMP'!$I$2:$I$1001))+ISNUMBER(SEARCH("buena pr",'Observaciones-SMP'!$I$2:$I$1001)))>0))>0))))
A30: INV(?) | B30: Investigaciones de accidentes cerradas en el mes | C30: u | D30: 0 | E30: 0
A31: INV(?) | B31: Días que llevaron esas investigaciones (suma) | C31: días | D31: 0 | E31: 0
B32: ACCIDENTES CON LESIÓN
A33: nDAFWC(ACDP) | B33: Casos con días perdidos | C33: u | D33: 0 | E33: 0
A34: nRWC(TR) | B34: Casos con trabajo restringido | C34: u | D34: 0 | E34: 0
A35: nMTC(TM) | B35: Casos con tratamiento médico | C35: u | D35: 0 | E35: 0
A36: nF(FA) | B36: Fatalidades | C36: u | D36: 0 | E36: 0
A37: FAC(PA) | B37: Casos de primeros auxilios | C37: u | D37: 0 | E37: 0
B38: ACCIDENTES VEHICULARES · CVM (Colisión de Vehículo Motor), categorías IOGP
A39: C(?) | B39: CVM catastróficas | C39: u | D39: 0 | E39: 0
A40: M(?) | B40: CVM mayores | C40: u | D40: 0 | E40: 0
...

Sheet Observaciones-SMP
A1: ID | B1: Fecha Apertura | C1: Observador | D1: Sector / Área del proyecto | E1: Especialidad | F1: Contratista | G1: Responsable | H1: Descripción | I1: Clasificación | J1: Regla de oro aplicable | K1: Ítems especifico (por fuera de regla de oro) | L1: Nivel de Riesgo/ IMPACTO | M1: Acción | N1: Aporte de documentos/registros | O1: Estado | P1: Tratamiento | Q1: Evidencia (antes) | R1: Evidencia (después) | S1: Fecha de cierre | T1: ¿Alto potencial?
A2: 2026-1 | B2: 46245 | C2: Karina Gentile IEBC | D2: Área 1 Obrador | E2: Civil | F2: OPS | G2: Civil | H2: Se observa la falta de identificación del punto de encuentro | I2: Desvío requisito legal | J2: Compromiso compartido | K2: Señalización y Sectorización | L2: Bajo | M2: Identificación | N2: Si | O2: Cerrado | P2: Supervisión | S2: 46249
A3: 2026-2 | B3: 46245 | C3: Karina Gentile IEBC | D3: Área 1 Obrador | E3: Electricidad e Instrumentos | F3: OPS | G3: Electricidad e Instrumentos | H3: Tablero eléctrico sin vallado perimetral. | I3: Condición subestándar | J3: Área de proyección y contacto | K3: Herramientas eléctricas y/o a baterias | L3: Bajo | M3: Señalizar y perimetral los tableros eléctricos. | N3: Si | O3: Cerrado | P3: Supervisión | S3: 46246
A4: 2026-3 | B4: 46245 | C4: Karina Gentile IEBC | D4: Área 1 Obrador | E4: Izaje | F4: SPUSA | G4: Izaje | H4: Se observa que la pasteca de la grúa se encuentra sin sujetar. | I4: Condición subestándar | J4: Operaciones de Izado | K4: Equipos de Izaje | L4: Bajo | M4: Se pidió que se mantenga siempre asegurada la pasteca. | N4: No Aplica | O4: Cerrado | P4: Supervisión | S4: 46246
A5: 2026-4 | B5: 46246 | C5: Karina Gentile IEBC | D5: Área 1 Obrador | E5: Logística | F5: OPS | G5: Logística | H5: Acopio con falta de señalización y delimitación de sectores. | I5: Condición subestándar | J5: Compromiso compartido | K5: Señalización y Sectorización | L5: Medio | M5: Identificación | N5: No Aplica | O5: Cerrado | P5: SSA Contratista | S5: 46249
A6: 2026-5 | B6: 46246 | C6: Karina Gentile IEBC | D6: Área 2 Est. Pesados | E6: Camiones Volcadores | F6: OPS | G6: Juan José Fernández (OPS) | H6: Se solicita determinar un sector para vehículos pesados | I6: Condición subestándar | J6: Seguridad Vial | K6: Señalización y Sectorización | L6: Bajo | M6: Identificación | N6: No | O6: Cerrado | P6: Supervisión | S6: 46249
A7: 2026-6 | B7: 46247 | C7: Mario Acosta IEBC | D7: Área 1 Obrador | E7: Logística | F7: OPS | G7: Juan José Fernández (OPS) | H7: Falta de arriostramientos de sujeción en las oficinas. | I7: Condición subestándar | J7: Área de proyección y contacto | K7: Otros | L7: Bajo | M7: Sujeción de las oficinas | N7: No | O7: En proceso | P7: Supervisión
A8: 2026-7 | B8: 46247 | C8: Mario Acosta IEBC | D8: Área 3 Pta. combustible | E8: Despacho de combustible Pta. | F8: OPS | G8: Logística | H8: Tablero eléctrico sin protecciones mecánicas. | I8: Condición subestándar | J8: Área de proyección y contacto | K8: Otros | L8: Medio | M8: Reacondicionar tableros e inst. elect. | N8: No Aplica | O8: Cerrado | P8: SSA Contratista | S8: 46249
A9: 2026-8 | B9: 46247 | C9: Mario Acosta IEBC | D9: Área 5 Mtto Mco. | E9: Mant. Mecánico | F9: OPS | G9: Lucas Antolínez (OPS MM) | H9: Clasificación de residuos mesclados. | I9: Desvío requisito legal | J9: Compromiso compartido | K9: Segregación de Residuos | L9: Bajo | M9: Charla / Capacitación | N9: Si | O9: Cerrado | P9: SSA Contratista | S9: 46248
A10: 2026-9 | B10: 46247 | C10: Mario Acosta IEBC | D10: Área 5 Mtto. Mco. | E10: Mant. Mecánico | F10: OPS | G10: Lucas Antolínez (OPS MM) | H10: Bomba de vacío sin bandeja secundaria. | I10: Desvío requisito legal | J10: Compromiso compartido | K10: Segregación de Residuos | L10: Bajo | M10: Charla / Capacitación | N10: Si | O10: Cerrado | P10: SSA Contratista | S10: 46249
A11: 2026-10 | B11: 46247 | C11: Mario Acosta IEBC | D11: Área 6 Lab. - baños | E11: Fumadores | F11: OPS | G11: SSGG | H11: Sector fumadores, falta cenicero y extintor | I11: Condición subestándar | J11: Compromiso compartido | K11: Otros | L11: Bajo | M11: Reacondicionar sector | N11: No Aplica | O11: Cerrado | P11: SSA Contratista | S11: 46248
A12: 2026-11 | B12: 46247 | C12: Mario Acosta IEBC | D12: Área 7 Prefabricados | E12: Soldadura | F12: OPS | G12: Juan José Fernández (OPS) | H12: Prefabricado de soldadura el uso de piquetas hechizas. | I12: Condición subestándar | J12: Línea de fuego | K12: Elementos y accesorios de izaje | L12: Bajo | M12: Reacondicionar sector | N12: No | O12: En proceso | P12: Jefatura de Obra
A13: 2026-12 | B13: 46247 | C13: Mario Acosta IEBC | D13: Área 8 Periferia | E13: Periferia | F13: OPS | G13: SSGG | H13: Residuos en los alrededores del obrador y futura planta compresora. | I13: Condición subestándar | J13: Compromiso compartido | K13: Orden y limpieza | L13: Bajo | M13: Charla / Capacitación | N13: Si | O13: Cerrado | P13: Jefatura de Obra | S13: 46253
A14: 2026-13 | B14: 46247 | C14: Mario Acosta IEBC | D14: Área 7 Prefabricados | E14: Soldadura | F14: OPS | G14: Juan José Fernández (OPS) | H14: Limpieza de rebarbas de soldadura, con disco de corte. | I14: Condición subestándar | J14: Área de proyección y contacto | K14: Herramientas eléctricas y/o a baterias | L14: Medio | M14: Proveer elementos faltantes | N14: No | O14: En proceso | P14: Jefatura de Obra
A15: 2026-14 | B15: 46248 | C15: Mario Acosta IEBC | D15: Área 2 Est. Pesados | E15: Izaje | F15: SPUSA | G15: Izaje | H15: Colocación de agropol sobre las eslingas de acero . | I15: Acto estándar | J15: Compromiso compartido | K15: Equipos de Izaje | L15: Bajo | M15: Acción | N15: No | O15: Cerrado | P15: Supervisión | S15: 46248
A16: 2026-15 | B16: 46248 | C16: Mario Acosta IEBC | D16: Área 4 Generadores | E16: Electricidad e Instrumentos | F16: OPS | G16: SSGG | H16: Tableros eléctricos de obra. Inspección mensual. | I16: Acto estándar | J16: Aislamiento de la Energía | K16: Señalización y Sectorización | L16: Bajo | M16: Acción | N16: No | O16: Cerrado | P16: SSA Contratista | S16: 46249
A17: 2026-16 | B17: 46249 | C17: Mario Acosta IEBC | D17: Área 4 Generadores | E17: Generación de energía | F17: OPS | G17: Electricidad e Instrumentos | H17: Generadores de energía, delimitación y completamiento con insumos ante derrame. | I17: Condición subestándar | J17: Aislamiento de la Energía | K17: Señalización y Sectorización | L17: Bajo | M17: Reacondicionar sector | N17: No | O17: Cerrado | P17: SSA Contratista | S17: 46250
A18: 2026-17 | B18: 46249 | C18: Mario Acosta IEBC | D18: Área 2 Est. Pesados | E18: Vehículos pesados y viales | F18: OPS | G18: Logística | H18: Estacionamiento de pesados y viales falta kit antiderrame. | I18: Condición subestándar | J18: Área de proyección y contacto | K18: Otros | L18: Bajo | M18: Proveer elementos faltantes | N18: No | O18: En proceso | P18: SSA Contratista
A19: 2026-18 | B19: 46249 | C19: Mario Acosta IEBC | D19: Área 9 Sendas peatonales | E19: Civil | F19: OPS | G19: Civil | H19: Clavos salientes en señalización. | I19: Condición subestándar | J19: Área de proyección y contacto | K19: Señalización y Sectorización | L19: Medio | M19: Reacondicionar sector | N19: No | O19: Cerrado | P19: SSA Contratista | S19: 46249
A20: 2026-19 | B20: 46252 | C20: Mario Acosta IEBC | D20: Área 8 Periferia | E20: Civil | F20: OPS | G20: Civil | H20: Residuos en los alrededores del obrador y futura planta compresora. | I20: Condición subestándar | J20: Compromiso compartido | K20: Orden y limpieza | L20: Bajo | M20: Levantamiento de residuos | N20: No | O20: Cerrado | P20: Jefatura de Obra | S20: 46252
A21: 2026-20 | B21: 46252 | C21: Mario Acosta IEBC | D21: Área 1 Obrador | E21: Logística | F21: OPS | G21: Juan José Fernández (OPS) | H21: Montaje de PAT + medición. | I21: Desvío requisito legal | J21: Aislamiento de la Energía | K21: Otros | L21: Bajo | M21: Acción | N21: Si | O21: Cerrado | P21: Jefatura de Obra | S21: 46254
A22: 2026-21 | B22: 46252 | C22: Mario Acosta IEBC | D22: Área 1 Obrador | E22: Logística | F22: OPS | G22: Juan José Fernández (OPS) | H22: Carga de fuego. | I22: Desvío requisito legal | K22: Otros | L22: Bajo | M22: Acción | N22: Si | O22: En proceso | P22: SSA Contratista
A23: 2026-22 | B23: 46252 | C23: Mario Acosta IEBC | D23: Área 2 Est. Pesados | E23: Vehículos pesados y viales | F23: CAT Finning | G23: Lucas Antolínez (OPS MM) | H23: AST sin firmar | I23: Desvío requisito legal | J23: Permiso de trabajo | K23: ATS | L23: Bajo | M23: Completamiento de documentos | N23: Aporte de documentos/registros | O23: Cerrado | P23: SSA Contratista | S23: 46252
A24: 2026-23 | B24: 46252 | C24: Mario Acosta IEBC | D24: Área 1 Obrador | E24: Electricidad e Instrumentos | F24: OPS | G24: Electricidad e Instrumentos | H24: Herramientas manuales sin cinta de inspección mensual | I24: Condición subestándar | J24: Área de proyección y contacto | K24: Herramientas eléctricas y/o a baterias | L24: Bajo | M24: Inspección de equipos y herramientas | N24: No | O24: Cerrado | P24: SSA Contratista | S24: 46254
A25: 2026-24 | B25: 46252 | C25: Mario Acosta IEBC | D25: Área 11 Plataforma de PC | E25: Laboratorio civil | F25: OPS | G25: Civil | H25: Uso de corta frio sin protección en manos, manopla. | I25: Condición subestándar | J25: Área de proyección y contacto | K25: Uso de EPP especifico | L25: Medio | M25: Proveer elementos faltantes | N25: No | O25: En proceso | P25: SSA Contratista
A26: 2026-25 | B26: 46252 | C26: Mario Acosta IEBC | D26: Área 11 Plataforma de PC | E26: Laboratorio civil | F26: OPS | G26: Civil | H26: Uso de caja de herramientas como banqueta. | I26: Condición subestándar | J26: Área de proyección y contacto | K26: Otros | L26: Bajo | M26: Proveer elementos faltantes | N26: No | O26: Cerrado | P26: SSA Contratista | S26: 46253
A27: 2026-26 | B27: 46252 | C27: Mario Acosta IEBC | D27: Área 6 Lab.- baños | E27: Logística | F27: OPS | G27: Logística | H27: Falta de agua en baños. Bomba de agua rota. | I27: Condición subestándar | J27: Compromiso compartido | K27: Orden y limpieza | L27: Bajo | M27: Retiro de elemento dañado | N27: No | O27: Cerrado | P27: SSA Contratista | S27: 46253
A28: 2026-27 | B28: 46252 | C28: Mario Acosta IEBC | D28: Área 8 Periferia | E28: Civil | F28: OPS | G28: Civil | H28: Acumulación de residuos en el perímetro de la obra. | I28: Condición subestándar | J28: Compromiso compartido | K28: Orden y limpieza | L28: Bajo | M28: Reacondicionar sector | N28: No | O28: Cerrado | P28: SSA Contratista | S28: 46253
A29: 2026-28 | B29: 46253 | C29: Mario Acosta IEBC | D29: Área 1 Obrador | E29: Pañol | F29: OPS | G29: Romina Segura (OPS) | H29: ATS sin confeccionar a las 09:00 hs | I29: Acto Subestándar | J29: Compromiso compartido | K29: ATS | L29: Bajo | M29: Completamiento de documentos | N29: Aporte de documentos/registros | O29: Cerrado | P29: SSA Contratista | S29: 46254
A30: 2026-29 | B30: 46253 | C30: Mario Acosta IEBC | D30: Área 1 Obrador | E30: Pañol | F30: OPS | G30: Romina Segura (OPS) | H30: Equipos y herramientas sin inspeccionar. | I30: Condición subestándar | J30: Compromiso compartido | K30: Herramientas eléctricas y/o a baterias | L30: Bajo | M30: Inspección de equipos y herramientas | N30: No | O30: Cerrado | P30: SSA Contratista | S30: 46255
A31: 2026-30 | B31: 46254 | C31: Mario Acosta IEBC | D31: Área 12 Ingreso desde Ruta N° 6 | E31: Logística | F31: OPS | G31: Juan José Fernández (OPS) | H31: Acumulación de residuos en zona mencionada | I31: Condición subestándar | J31: Compromiso compartido | K31: Orden y limpieza | L31: Bajo | M31: Charla / Capacitación | N31: Si | O31: Cerrado | P31: Jefatura de Obra | S31: 46254
A32: 2026-31 | B32: 46254 | C32: Mario Acosta IEBC | D32: Área 11 Plataforma de PC | E32: Vehículos pesados y viales | F32: OPS | G32: Civil | H32: Falta de paleta PARE - SIGA para señalero en descarga de material. | I32: Acto Subestándar | J32: Gestión de cambio | K32: Otros | L32: Bajo | M32: Proveer elementos faltantes | N32: No | O32: Cerrado | P32: Supervisión | S32: 46254
A33: 2026-32 | B33: 46254 | C33: Mario Acosta IEBC | D33: Área 5 Mtto. Mecánico. | E33: Mant. Mecánico | F33: OPS | G33: Lucas Antolínez (OPS MM) | H33: Faja de traca traca cortada. Fuera ed servicio. | I33: Condición subestándar | J33: Gestión de cambio | K33: Elementos y accesorios de izaje | L33: Medio | M33: Retiro de elemento dañado | N33: No | O33: Cerrado | P33: Supervisión | S33: 46254
A34: 2026-33 | B34: 46254 | C34: Mario Acosta IEBC | D34: Área 13 Acopio contenedores de residuos | E34: Maestranza | F34: OPS | G34: Serge | H34: Armado de acopio de residuos | I34: Condición estándar | J34: Gestión de cambio | K34: Orden y limpieza | L34: Bajo | M34: Reconocimiento | N34: No Aplica | O34: Cerrado | P34: SSA Contratista | S34: 38950
A35: 2026-34 | B35: 46255 | C35: Mario Acosta IEBC | D35: Área 10 Sector de hormigonado | E35: Civil | F35: OPS | G35: Civil | H35: Equipos del sector de hormigonado sin sticker de insp. Mensual. | I35: Condición subestándar | J35: Compromiso compartido | K35: Herramientas eléctricas y/o a baterias | L35: Bajo | M35: Inspección de equipos y herramientas | N35: No | O35: Cerrado | P35: SSA Contratista | S35: 46255
A36: 2026-35 | B36: 46255 | C36: Mario Acosta IEBC | D36: Área 10 Sector de hormigonado | E36: Logística | F36: OPS | G36: Civil | H36: Generador de corriente sin extintor | I36: Condición subestándar | J36: Compromiso compartido | K36: Otros | L36: Bajo | M36: Proveer elementos faltantes | N36: No | O36: Cerrado | P36: SSA Contratista | S36: 46255
A37: 2026-36 | B37: 46275 | C37: Mario Acosta | D37: Area 18 Planta de H°A° | E37: Civil | F37: OPS | G37: Sanhuesa Dario (OPS Sup. Civil) | H37: Acopio de lats de 20 lt s con Solventes sin bandeja de contención | I37: Condicion subestándard | J37: Compromiso compartido | K37: Otros | L37: Bajo | M37: Levantamiento de residuos | N37: No | O37: Cerrado | P37: Supervisión
A38: 2026-37 | B38: 46277 | C38: Mario Acosta | D38: Área 7 Soldadura | E38: Soldadura | F38: OPS | G38: Ortega Ruben (Piping) | H38: Trabajos de biselado de codo, se obsea la falta de panatlallas protectoras. | I38: Condicion subestándard | J38: Línea de fuego | K38: Señalización y Sectorización | L38: Bajo | M38: Reacondicionar sector | N38: No | O38: Abierto | P38: Supervisión
A39: 2026-38 | B39: 46277 | C39: Mario Acosta | D39: Área 8 Periferia | E39: Logistica | F39: OPS | G39: Juan Jose Fernandez (OPS) | H39: Se hace control de los recipientes de residuos y se observa segregación inadecuada. | I39: Acto Subestándard | J39: Compromiso compartido | K39: Acopio de materiales | L39: Bajo | M39: Levantamiento de residuos | N39: No | O39: Cerrado | P39: Supervisión
A40: 2026-39 | B40: 46277 | C40: Mario Acosta | D40: Área 14 Porteria de acceso | E40: Seguridad Patrimonial | F40: Contratista | G40: Frank Marco (Grupo SEI) | H40: Se observa la no utilización de lentes transparentes. | I40: Acto Subestándard | J40: Compromiso compartido | K40: Uso de EPP especifico | L40: Bajo | M40: Proveer elementos faltantes | N40: No | O40: Abierto
...

Sheet MAPs
A1: ID | B1: Fecha Apertura | C1: Observador | D1: Sector / Área del proyecto | E1: Especialidad | F1: Contratista | G1: Responsable | H1: Descripción | I1: Clasificación | J1: Regla de oro aplicable | K1: Ítems especifico (por fuera de regla de oro) | L1: Nivel de Riesgo/ IMPACTO | M1: Acción | N1: Aporte de documentos/registros | O1: Estado | P1: Tratamiento | Q1: Evidencia (antes) | R1: Evidencia (después) | S1: Fecha de cierre | T1: ¿Alto potencial?

Sheet KPIs
A1: KPIs HSE · Planta Compresora · OPS + SMP(IEBC, PAE e YPF) en campo · San Matías Pipeline
A2: Verde = cumple la meta · Rojo = no cumple · "-" = mes sin datos. Columna META automática; las metas de _TARGETS se modifican únicamente al desproteger con la clave. Violeta = meta de simulación.
A3: INDICADOR | B3: CÓMO SE CALCULA | C3: TARGET / META | D3: 46235 | E3: 46266 | F3: 46296 | G3: 46327 | H3: 46357 | I3: 46388 | J3: 46419 | K3: 46447 | L3: 46478 | M3: 46508 | N3: 46539 | O3: 46569 | P3: 46600 | Q3: 46631 | R3: 46661 | S3: 46692 | T3: 46722 | U3: 46753 | V3: 46784 | W3: 46813 | X3: 46844 | Y3: 46874 | Z3: 46905 | AA3: 46935 | AB3: 46966 | AC3: 46997 | AD3: 47027 | AE3: 47058 | AF3: 47088 | AG3: 47119 | AH3: 47150 | AI3: 47178 | AJ3: 47209 | AK3: 47239 | AL3: 47270
D4: Compresora | E4: Compresora | F4: Compresora | G4: Compresora | H4: Compresora | I4: Compresora | J4: Compresora | K4: Compresora | L4: Compresora | M4: Compresora | N4: Compresora | O4: Compresora | P4: Compresora | Q4: Compresora | R4: Compresora | S4: Compresora | T4: Compresora | U4: Compresora | V4: Compresora | W4: Compresora | X4: Compresora | Y4: Compresora | Z4: Compresora | AA4: Compresora | AB4: Compresora | AC4: Compresora | AD4: Compresora | AE4: Compresora | AF4: Compresora | AG4: Compresora | AH4: Compresora | AI4: Compresora | AJ4: Compresora | AK4: Compresora | AL4: Compresora
A5: INDICADORES REACTIVOS · Personal
A6: 1 · Frecuencia de casos con días perdidos | B6: nDAFWC × 1.000.000 ÷ HHT | C6: =INDEX(_TARGETS!$F$2:$F$17,MATCH("DAFWCF",_TARGETS!$A$2:$A$17,0)) -> 0 | D6: =IF(Datos!D14=0,"-",Datos!D33*1000000/Datos!D14) -> 0 | E6: =IF(Datos!E14=0,"-",Datos!E33*1000000/Datos!E14) -> 0 | F6: =IF(Datos!F14=0,"-",Datos!F33*1000000/Datos!F14) -> - | G6: =IF(Datos!G14=0,"-",Datos!G33*1000000/Datos!G14) -> - | H6: =IF(Datos!H14=0,"-",Datos!H33*1000000/Datos!H14) -> - | I6: =IF(Datos!I14=0,"-",Datos!I33*1000000/Datos!I14) -> - | J6: =IF(Datos!J14=0,"-",Datos!J33*1000000/Datos!J14) -> - | K6: =IF(Datos!K14=0,"-",Datos!K33*1000000/Datos!K14) -> - | ... AL6: =IF(Datos!AL14=0,"-",Datos!AL33*1000000/Datos!AL14) -> -
A7: 2 · Frecuencia de casos registrables | B7: (nDAFWC + nRWC + nMTC + nF) × 1.000.000 ÷ HHT (sin primeros auxilios) | C7: =INDEX(_TARGETS!$F$2:$F$17,MATCH("TRICF",_TARGETS!$A$2:$A$17,0)) -> 2.35 | D7: =IF(Datos!D14=0,"-",(Datos!D33+Datos!D34+Datos!D35+Datos!D36)*1000000/Datos!D14) -> 0 | E7: =IF(Datos!E14=0,"-",(Datos!E33+Datos!E34+Datos!E35+Datos!E36)*1000000/Datos!E14) -> 0 | F7: =IF(Datos!F14=0,"-",(Datos!F33+Datos!F34+Datos!F35+Datos!F36)*1000000/Datos!F14) -> - | G7: =IF(Datos!G14=0,"-",(Datos!G33+Datos!G34+Datos!G35+Datos!G36)*1000000/Datos!G14) -> - | H7: =IF(Datos!H14=0,"-",(Datos!H33+Datos!H34+Datos!H35+Datos!H36)*1000000/Datos!H14) -> - | I7: =IF(Datos!I14=0,"-",(Datos!I33+Datos!I34+Datos!I35+Datos!I36)*1000000/Datos!I14) -> - | J7: =IF(Datos!J14=0,"-",(Datos!J33+Datos!J34+Datos!J35+Datos!J36)*1000000/Datos!J14) -> - | K7: =IF(Datos!K14=0,"-",(Datos!K33+Datos!K34+Datos!K35+Datos!K36)*1000000/Datos!K14) -> - | ... AL7: =IF(Datos!AL14=0,"-",(Datos!AL33+Datos!AL34+Datos!AL35+Datos!AL36)*1000000/Datos!AL14) -> -
A8: 3 · Casos de primeros auxilios | B8: Cantidad de casos en el mes | C8: =INDEX(_TARGETS!$F$2:$F$17,MATCH("FAC",_TARGETS!$A$2:$A$17,0)) -> Reporte | D8: =IF(Datos!D14=0,"-",Datos!D37) -> 0 | E8: =IF(Datos!E14=0,"-",Datos!E37) -> 0 | F8: =IF(Datos!F14=0,"-",Datos!F37) -> - | G8: =IF(Datos!G14=0,"-",Datos!G37) -> - | H8: =IF(Datos!H14=0,"-",Datos!H37) -> - | I8: =IF(Datos!I14=0,"-",Datos!I37) -> - | J8: =IF(Datos!J14=0,"-",Datos!J37) -> - | K8: =IF(Datos!K14=0,"-",Datos!K37) -> - | ... AL8: =IF(Datos!AL14=0,"-",Datos!AL37) -> -
A9: INDICADORES REACTIVOS · Vehiculares
A10: 4 · Accidentes vehiculares severos por millón de km | B10: (C + M + S) × 1.000.000 ÷ km recorridos | C10: =INDEX(_TARGETS!$F$2:$F$17,MATCH("SVCR",_TARGETS!$A$2:$A$17,0)) -> Reporte | D10: =IF(Datos!D47=0,"-",(Datos!D39+Datos!D40+Datos!D41)*1000000/Datos!D47) -> 0 | E10: =IF(Datos!E47=0,"-",(Datos!E39+Datos!E40+Datos!E41)*1000000/Datos!E47) -> 0 | F10: =IF(Datos!F47=0,"-",(Datos!F39+Datos!F40+Datos!F41)*1000000/Datos!F47) -> - | G10: =IF(Datos!G47=0,"-",(Datos!G39+Datos!G40+Datos!G41)*1000000/Datos!G47) -> - | H10: =IF(Datos!H47=0,"-",(Datos!H39+Datos!H40+Datos!H41)*1000000/Datos!H47) -> - | I10: =IF(Datos!I47=0,"-",(Datos!I39+Datos!I40+Datos!I41)*1000000/Datos!I47) -> - | J10: =IF(Datos!J47=0,"-",(Datos!J39+Datos!J40+Datos!J41)*1000000/Datos!J47) -> - | K10: =IF(Datos!K47=0,"-",(Datos!K39+Datos!K40+Datos!K41)*1000000/Datos!K47) -> - | ... AL10: =IF(Datos!AL47=0,"-",(Datos!AL39+Datos!AL40+Datos!AL41)*1000000/Datos!AL47) -> -
A11: 5 · Accidentes vehiculares totales por millón de km | B11: (C + M + S + O) × 1.000.000 ÷ km recorridos | C11: =INDEX(_TARGETS!$F$2:$F$17,MATCH("TVCR",_TARGETS!$A$2:$A$17,0)) -> 0.79 | D11: =IF(Datos!D47=0,"-",(Datos!D39+Datos!D40+Datos!D41+Datos!D42)*1000000/Datos!D47) -> 0 | E11: =IF(Datos!E47=0,"-",(Datos!E39+Datos!E40+Datos!E41+Datos!E42)*1000000/Datos!E47) -> 0 | F11: =IF(Datos!F47=0,"-",(Datos!F39+Datos!F40+Datos!F41+Datos!F42)*1000000/Datos!F47) -> - | G11: =IF(Datos!G47=0,"-",(Datos!G39+Datos!G40+Datos!G41+Datos!G42)*1000000/Datos!G47) -> - | H11: =IF(Datos!H47=0,"-",(Datos!H39+Datos!H40+Datos!H41+Datos!H42)*1000000/Datos!H47) -> - | I11: =IF(Datos!I47=0,"-",(Datos!I39+Datos!I40+Datos!I41+Datos!I42)*1000000/Datos!I47) -> - | J11: =IF(Datos!J47=0,"-",(Datos!J39+Datos!J40+Datos!J41+Datos!J42)*1000000/Datos!J47) -> - | K11: =IF(Datos!K47=0,"-",(Datos!K39+Datos!K40+Datos!K41+Datos!K42)*1000000/Datos!K47) -> - | ... AL11: =IF(Datos!AL47=0,"-",(Datos!AL39+Datos!AL40+Datos!AL41+Datos!AL42)*1000000/Datos!AL47) -> -
A12: INDICADORES REACTIVOS · Gestión
A13: 6 · Observaciones de seguridad por persona | B13: Nº de observaciones de comportamiento seguro ÷ dotación promedio | C13: =INDEX(_TARGETS!$F$2:$F$17,MATCH("OBS",_TARGETS!$A$2:$A$17,0)) -> 1 | D13: =IF(OR(Datos!D11=0,COUNT(Datos!D28:D29)=0),"-",SUM(Datos!D28:D29)/Datos!D11) -> 0.38043478 | E13: =IF(OR(Datos!E11=0,COUNT(Datos!E28:E29)=0),"-",SUM(Datos!E28:E29)/Datos!E11) -> 1.4390244 | F13: =IF(OR(Datos!F11=0,COUNT(Datos!F28:F29)=0),"-",SUM(Datos!F28:F29)/Datos!F11) -> - | G13: =IF(OR(Datos!G11=0,COUNT(Datos!G28:G29)=0),"-",SUM(Datos!G28:G29)/Datos!G11) -> - | H13: =IF(OR(Datos!H11=0,COUNT(Datos!H28:H29)=0),"-",SUM(Datos!H28:H29)/Datos!H11) -> - | I13: =IF(OR(Datos!I11=0,COUNT(Datos!I28:I29)=0),"-",SUM(Datos!I28:I29)/Datos!I11) -> - | J13: =IF(OR(Datos!J11=0,COUNT(Datos!J28:J29)=0),"-",SUM(Datos!J28:J29)/Datos!J11) -> - | K13: =IF(OR(Datos!K11=0,COUNT(Datos!K28:K29)=0),"-",SUM(Datos!K28:K29)/Datos!K11) -> - | ... AL13: =IF(OR(Datos!AL11=0,COUNT(Datos!AL28:AL29)=0),"-",SUM(Datos!AL28:AL29)/Datos!AL11) -> -
A14: 7 · Investigaciones de accidentes: días promedio de cierre | B14: Días de las investigaciones cerradas ÷ Nº de cerradas | C14: =INDEX(_TARGETS!$F$2:$F$17,MATCH("INV",_TARGETS!$A$2:$A$17,0)) -> 20 | D14: =IF(Datos!D30=0,"-",Datos!D31/Datos!D30) -> - | E14: =IF(Datos!E30=0,"-",Datos!E31/Datos!E30) -> - | F14: =IF(Datos!F30=0,"-",Datos!F31/Datos!F30) -> - | G14: =IF(Datos!G30=0,"-",Datos!G31/Datos!G30) -> - | H14: =IF(Datos!H30=0,"-",Datos!H31/Datos!H30) -> - | I14: =IF(Datos!I30=0,"-",Datos!I31/Datos!I30) -> - | J14: =IF(Datos!J30=0,"-",Datos!J31/Datos!J30) -> - | K14: =IF(Datos!K30=0,"-",Datos!K31/Datos!K30) -> - | ... AL14: =IF(Datos!AL30=0,"-",Datos!AL31/Datos!AL30) -> -
A15: INDICADORES PROACTIVOS · Personal y vehiculares
A16: 8 · % de capacitación en seguridad | B16: HH de capacitación en seguridad ÷ HHT | C16: =INDEX(_TARGETS!$F$2:$F$17,MATCH("HCS",_TARGETS!$A$2:$A$17,0)) -> 0.01 | D16: =IF(Datos!D14=0,"-",Datos!D18/Datos!D14) -> 0.054811206 | E16: =IF(Datos!E14=0,"-",Datos!E18/Datos!E14) -> 0.03515625 | F16: =IF(Datos!F14=0,"-",Datos!F18/Datos!F14) -> - | G16: =IF(Datos!G14=0,"-",Datos!G18/Datos!G14) -> - | H16: =IF(Datos!H14=0,"-",Datos!H18/Datos!H14) -> - | I16: =IF(Datos!I14=0,"-",Datos!I18/Datos!I14) -> - | J16: =IF(Datos!J14=0,"-",Datos!J18/Datos!J14) -> - | K16: =IF(Datos!K14=0,"-",Datos!K18/Datos!K14) -> - | ... AL16: =IF(Datos!AL14=0,"-",Datos!AL18/Datos!AL14) -> -
A17: 9 · Horas de capacitación por persona | B17: HH de capacitación en seguridad ÷ dotación promedio | C17: =INDEX(_TARGETS!$F$2:$F$17,MATCH("HCSA",_TARGETS!$A$2:$A$17,0)) -> Reporte | D17: =IF(Datos!D11=0,"-",Datos!D18/Datos!D11) -> 13.695652 | E17: =IF(Datos!E11=0,"-",Datos!E18/Datos!E11) -> 7.2439024 | F17: =IF(Datos!F11=0,"-",Datos!F18/Datos!F11) -> - | G17: =IF(Datos!G11=0,"-",Datos!G18/Datos!G11) -> - | H17: =IF(Datos!H11=0,"-",Datos!H18/Datos!H11) -> - | I17: =IF(Datos!I11=0,"-",Datos!I18/Datos!I11) -> - | J17: =IF(Datos!J11=0,"-",Datos!J18/Datos!J11) -> - | K17: =IF(Datos!K11=0,"-",Datos!K18/Datos!K11) -> - | ... AL17: =IF(Datos!AL11=0,"-",Datos!AL18/Datos!AL11) -> -
A18: 10 · Cumplimiento de simulacros (emergencia y operativos) | B18: Simulacros realizados ÷ programados (emergencia y operativos) | C18: =INDEX(_TARGETS!$F$2:$F$17,MATCH("CPSE",_TARGETS!$A$2:$A$17,0)) -> 1 | D18: =IF(Datos!D21=0,"-",Datos!D20/Datos!D21) -> 1 | E18: =IF(Datos!E21=0,"-",Datos!E20/Datos!E21) -> 1 | F18: =IF(Datos!F21=0,"-",Datos!F20/Datos!F21) -> - | G18: =IF(Datos!G21=0,"-",Datos!G20/Datos!G21) -> - | H18: =IF(Datos!H21=0,"-",Datos!H20/Datos!H21) -> - | I18: =IF(Datos!I21=0,"-",Datos!I20/Datos!I21) -> - | J18: =IF(Datos!J21=0,"-",Datos!J20/Datos!J21) -> - | K18: =IF(Datos!K21=0,"-",Datos!K20/Datos!K21) -> - | ... AL18: =IF(Datos!AL21=0,"-",Datos!AL20/Datos!AL21) -> -
A19: 10b · Cumplimiento de acciones de mejora de simulacros | B19: Acciones de mejora implementadas ÷ surgidas de los simulacros, ICME (sin meta definida) | C19: =INDEX(_TARGETS!$F$2:$F$17,MATCH("CAMS",_TARGETS!$A$2:$A$17,0)) -> Reporte | D19: =IF(Datos!D22=0,"-",Datos!D23/Datos!D22) -> - | E19: =IF(Datos!E22=0,"-",Datos!E23/Datos!E22) -> 1 | F19: =IF(Datos!F22=0,"-",Datos!F23/Datos!F22) -> - | G19: =IF(Datos!G22=0,"-",Datos!G23/Datos!G22) -> - | H19: =IF(Datos!H22=0,"-",Datos!H23/Datos!H22) -> - | I19: =IF(Datos!I22=0,"-",Datos!I23/Datos!I22) -> - | J19: =IF(Datos!J22=0,"-",Datos!J23/Datos!J22) -> - | K19: =IF(Datos!K22=0,"-",Datos!K23/Datos!K22) -> - | ... AL19: =IF(Datos!AL22=0,"-",Datos!AL23/Datos!AL22) -> -
A20: INDICADORES PROACTIVOS · Gestión
